Workbook

Sheet iris
A1: Sepal.Length | B1: Sepal.Width | C1: Petal.Length | D1: Petal.Width | E1: Species
A2: 5.1 | B2: 3.5 | C2: 1.4 | D2: 0.2 | E2: setosa
A3: 4.9 | B3: 3 | C3: 1.4 | D3: 0.2 | E3: setosa
A4: 4.7 | B4: 3.2 | C4: 1.3 | D4: 0.2 | E4: setosa
A5: 4.6 | B5: 3.1 | C5: 1.5 | D5: 0.2 | E5: setosa
A6: 5 | B6: 3.6 | C6: 1.4 | D6: 0.2 | E6: setosa
A7: 5.4 | B7: 3.9 | C7: 1.7 | D7: 0.4 | E7: setosa
A8: 4.6 | B8: 3.4 | C8: 1.4 | D8: 0.3 | E8: setosa
A9: 5 | B9: 3.4 | C9: 1.5 | D9: 0.2 | E9: setosa
A10: 4.4 | B10: 2.9 | C10: 1.4 | D10: 0.2 | E10: setosa
A11: 4.9 | B11: 3.1 | C11: 1.5 | D11: 0.1 | E11: setosa
A12: 5.4 | B12: 3.7 | C12: 1.5 | D12: 0.2 | E12: setosa
A13: 4.8 | B13: 3.4 | C13: 1.6 | D13: 0.2 | E13: setosa
A14: 4.8 | B14: 3 | C14: 1.4 | D14: 0.1 | E14: setosa
A15: 4.3 | B15: 3 | C15: 1.1 | D15: 0.1 | E15: setosa
A16: 5.8 | B16: 4 | C16: 1.2 | D16: 0.2 | E16: setosa
A17: 5.7 | B17: 4.4 | C17: 1.5 | D17: 0.4 | E17: setosa
A18: 5.4 | B18: 3.9 | C18: 1.3 | D18: 0.4 | E18: setosa
A19: 5.1 | B19: 3.5 | C19: 1.4 | D19: 0.3 | E19: setosa
A20: 5.7 | B20: 3.8 | C20: 1.7 | D20: 0.3 | E20: setosa
A21: 5.1 | B21: 3.8 | C21: 1.5 | D21: 0.3 | E21: setosa
A22: 5.4 | B22: 3.4 | C22: 1.7 | D22: 0.2 | E22: setosa
A23: 5.1 | B23: 3.7 | C23: 1.5 | D23: 0.4 | E23: setosa
A24: 4.6 | B24: 3.6 | C24: 1 | D24: 0.2 | E24: setosa
A25: 5.1 | B25: 3.3 | C25: 1.7 | D25: 0.5 | E25: setosa
A26: 4.8 | B26: 3.4 | C26: 1.9 | D26: 0.2 | E26: setosa
A27: 5 | B27: 3 | C27: 1.6 | D27: 0.2 | E27: setosa
A28: 5 | B28: 3.4 | C28: 1.6 | D28: 0.4 | E28: setosa
A29: 5.2 | B29: 3.5 | C29: 1.5 | D29: 0.2 | E29: setosa
A30: 5.2 | B30: 3.4 | C30: 1.4 | D30: 0.2 | E30: setosa
A31: 4.7 | B31: 3.2 | C31: 1.6 | D31: 0.2 | E31: setosa
A32: 4.8 | B32: 3.1 | C32: 1.6 | D32: 0.2 | E32: setosa
A33: 5.4 | B33: 3.4 | C33: 1.5 | D33: 0.4 | E33: setosa
A34: 5.2 | B34: 4.1 | C34: 1.5 | D34: 0.1 | E34: setosa
A35: 5.5 | B35: 4.2 | C35: 1.4 | D35: 0.2 | E35: setosa
A36: 4.9 | B36: 3.1 | C36: 1.5 | D36: 0.2 | E36: setosa
A37: 5 | B37: 3.2 | C37: 1.2 | D37: 0.2 | E37: setosa
A38: 5.5 | B38: 3.5 | C38: 1.3 | D38: 0.2 | E38: setosa
A39: 4.9 | B39: 3.6 | C39: 1.4 | D39: 0.1 | E39: setosa
A40: 4.4 | B40: 3 | C40: 1.3 | D40: 0.2 | E40: setosa
...

Sheet Análise do Dataset Iris
B2: Análise do Conjunto de Dados Iris
B3: Categorias Unicas: | D3: {=_xlfn.UNIQUE(iris!E2:E151)} -> setosa | F3: {=(TRANSPOSE(iris!A1:E1))} -> Sepal.Length | G3: =(_xlfn.TRANSLATE(F3)) -> Sepal.Comprimento
D4: versicolor | F4: Sepal.Width | G4: =(_xlfn.TRANSLATE(F4)) -> Sepal.Width
D5: virginica | F5: Petal.Length | G5: =(_xlfn.TRANSLATE(F5)) -> Pétala. Comprimento
B6: Frequência Absoluta: | C6: setosa | D6: =COUNTIF(iris!E2:E151,'Análise do Dataset Iris'!C6) -> 50 | F6: Petal.Width | G6: =(_xlfn.TRANSLATE(F6)) -> Pétala. Largura
C7: versicolor | D7: =COUNTIF(iris!E2:E151,'Análise do Dataset Iris'!C7) -> 50 | F7: Species | G7: =(_xlfn.TRANSLATE(F7)) -> Espécies
C8: virginica | D8: =COUNTIF(iris!E2:E153,'Análise do Dataset Iris'!C8) -> 50
B9: Total de Linhas: | D9: =(COUNTA(iris!E1:E150)) -> 150
B10: Frequência Relativa: | C10: setosa | D10: =D6/$D$9 -> 0.33333333
C11: versicolor | D11: =D7/$D$9 -> 0.33333333
C12: virginica | D12: =D8/$D$9 -> 0.33333333
B13: Frequência Relativa (em porcentagem %): | C13: setosa | D13: =D10 -> 0.33333333
C14: versicolor | D14: =D11 -> 0.33333333
C15: virginica | D15: =D12 -> 0.33333333
B16: Média Total | C16: {=TRANSPOSE(iris!$A$1:'iris'!$D$1)} -> Sepal.Length | D16: =(AVERAGE(iris!A2:A151)) -> 5.4705882 | E16: Fórmula: AVERAGE = Média.
C17: Sepal.Width | D17: =(AVERAGE(iris!B2:B151)) -> 3
C18: Petal.Length | D18: =(AVERAGE(iris!C2:C151)) -> 4.3076923
C19: Petal.Width | D19: =(AVERAGE(iris!D2:D151)) -> 1.4615385
B20: Média | D20: =AVERAGEIF(iris!E2:E151,"setosa",iris!C2:C151) -> 1
D21: =AVERAGEIF(iris!E2:E151,"versicolor",iris!C2:C151) -> 4
D22: =AVERAGEIF(iris!E2:E151,"virginica",iris!C2:C151) -> 5.4
B23: Mediana Total | C23: {=TRANSPOSE(iris!$A$1:'iris'!$D$1)} -> Sepal.Length | D23: =(MEDIAN(iris!A2:A151)) -> 5 | E23: Fórmula: MEDIAN = Mediana.
C24: Sepal.Width | D24: =(MEDIAN(iris!B2:B151)) -> 3
C25: Petal.Length | D25: =(MEDIAN(iris!C2:C151)) -> 4
C26: Petal.Width | D26: =(MEDIAN(iris!D2:D151)) -> 1
B31: Desvio padrão Total | C31: {=TRANSPOSE(iris!$A$1:'iris'!$D$1)} -> Sepal.Length | D31: =(_xlfn.STDEV.S(iris!A2:A151)) -> 0.62426427 | E31: Fórmula: STDEV.S ST → Standard DEV → Deviation S → Sample Standard Deviation (Sample) Desvio padrão amostral
C32: Sepal.Width | D32: =(_xlfn.STDEV.S(iris!B2:B151)) -> 0.27216553
C33: Petal.Length | D33: =(_xlfn.STDEV.S(iris!C2:C151)) -> 1.315587
C34: Petal.Width | D34: =(_xlfn.STDEV.S(iris!D2:D151)) -> 0.51887452
B35: Variância Total | C35: {=TRANSPOSE(iris!$A$1:'iris'!$D$1)} -> Sepal.Length | D35: =(_xlfn.VAR.S(iris!A2:A151)) -> 0.38970588 | E35: Fórmula: VAR.S VAR → Variance S → Sample Variância amostral
C36: Sepal.Width | D36: =(_xlfn.VAR.S(iris!B2:B151)) -> 0.074074074
C37: Petal.Length | D37: =(_xlfn.VAR.S(iris!C2:C151)) -> 1.7307692
C38: Petal.Width | D38: =(_xlfn.VAR.S(iris!D2:D151)) -> 0.26923077
